Workbook

Sheet Notice
A1: Outillage IA — recherche réglementaire sécurité incendie
A2: Livrables des étapes 1 et 2 de la méthode de conception
A4: Version | B4: 1.0.0
A5: Date | B5: 2026-07-30
A6: Périmètre | B6: ERP (arr. 25/06/1980) — Code du travail 4e partie — Habitation (CCH + arr. 31/01/1986)
A8: AVERTISSEMENT
A9: Les références d'articles sont des POINTS D'ENTRÉE, à vérifier dans la version en vigueur.
A10: La colonne confiance_reference vaut 'haute' ou 'a_verifier'.
A11: Aucune référence ne doit être restituée à un utilisateur final sans validation experte préalable.
A12: Recodifications à traiter : CCH R. 123-x -> R. 143-x et L. 129-8 -> L. 142-2 (2021) ;
A13: code du travail R. 232-12 et s. -> R. 4227-1 et s. (2008).
A15: MODE D'EMPLOI
A16: Les cellules à fond jaune sont celles que l'expert renseigne (validation, réponse système).
A17: Onglet Thésaurus : valider terme par terme. Colonne VALIDATION_EXPERT = OK / A CORRIGER / A SUPPRIMER.
A18: Onglet Jeu_référence : mesure du rappel des articles et du comportement attendu.
A19: Onglet Jeu_adverse : mesure la résistance aux pièges. C'est ce jeu qui décide d'une mise en production.
A20: Onglet Assertions_négatives : à indexer comme documents à part entière dans la base.
A21: Les deux jeux ne doivent JAMAIS servir à l'entraînement : ils mesurent, ils n'apprennent pas.

Sheet Thésaurus
A1: id | B1: theme | C1: terme_prefere | D1: definition | E1: synonymes_usage | F1: termes_obsoletes | G1: faux_amis | H1: corpus_ERP | I1: corpus_CT | J1: corpus_HAB | K1: autres_sources | L1: variables_determinantes | M1: niveau_normativite | N1: stade | O1: profils | P1: note_preventionniste | Q1: confiance_reference | R1: VALIDATION_EXPERT
A2: NOT-0001 | B2: T1 — Classement, champ d'application, seuils | C2: type d'exploitation | D2: Lettre caractérisant la nature de l'activité d'un ERP et commandant les dispositions particulières applicables. | E2: nature de l'activité | usage du bâtiment | c'est un magasin / un bureau / une salle | H2: GN 1 | GN 2 | L2: type_erp | presence_public | M2: reglementaire | N2: conception | exploitation | O2: architecte | P2: Sans type ni catégorie, aucune recherche ERP n'aboutit : presque tout est conditionnel. | Q2: a_verifier
A3: NOT-0002 | B3: T1 — Classement, champ d'application, seuils | C3: catégorie | D3: Classe de 1re à 5e déterminée par l'effectif admissible, commandant l'étendue des exigences. | E3: quelle catégorie | je suis en combien | c'est un petit ERP | G3: catégorie [ICPE] : chez un dirigeant, désigne souvent un régime ICPE (déclaration/enregistrement/autorisation) | catégorie [HAB] : en habitation la notion pertinente est la famille, pas la catégorie | H3: GN 1 | GN 2 | K3: CCH R. 143-19 (ex-R. 123-19) | L3: categorie_erp | effectif_public | M3: reglementaire | N3: conception | exploitation | O3: architecte | dirigeant | P3: PIÈGE N°1 : faire préciser le corpus avant de chercher le mot « catégorie ». | Q3: a_verifier
A4: NOT-0003 | B4: T1 — Classement, champ d'application, seuils | C4: effectif théorique du public | D4: Effectif calculé selon les règles propres à chaque type, servant au classement et au calcul des dégagements. | E4: combien de personnes je peux recevoir | la jauge | capacité d'accueil | H4: GN 1 | GN 2 | dispositions particulières au type | L4: effectif_public | type_erp | M4: reglementaire | N4: conception | exploitation | O4: architecte | P4: Trois modes possibles : déclaration, ratio surfacique, nombre de places. Ne pas confondre avec l'effectif du personnel. | Q4: a_verifier
A5: NOT-0004 | B5: T1 — Classement, champ d'application, seuils | C5: effectif (décompte code du travail) | D5: Effectif des travailleurs décompté selon les règles du code du travail, déclenchant certains seuils de prévention. | E5: combien de salariés | mes effectifs | on est une petite boîte | I5: L. 1111-2 | L. 1111-3 | R. 4227-34 | R. 4227-37 | L5: effectif_travailleurs | M5: reglementaire | N5: conception | exploitation | O5: dirigeant | P5: Périmètre différent de l'effectif ERP : intérimaires, alternants et mis à disposition suivent des règles propres. | Q5: a_verifier
A6: NOT-0005 | B6: T1 — Classement, champ d'application, seuils | C6: famille | D6: Classe (1re, 2e, 3e A, 3e B, 4e) des bâtiments d'habitation déterminée par le nombre d'étages, la hauteur du plancher bas et l'accès des secours. | E6: mon immeuble est en quelle catégorie | petit collectif | grande tour | J6: arr. 31/01/1986 art. 3 | L6: famille_habitation | nb_niveaux | hauteur_plancher_bas | M6: reglementaire | N6: conception | exploitation | O6: gestionnaire | architecte | P6: Équivalent fonctionnel de la catégorie ERP. Le gestionnaire dit souvent « catégorie » : reformuler. | Q6: haute
A7: NOT-0006 | B7: T1 — Classement, champ d'application, seuils | C7: groupement d'établissements | D7: Ensemble d'établissements de types divers réunis dans un même bâtiment ou juxtaposés, classé et isolé selon des règles propres. | E7: centre commercial | plusieurs activités dans le même bâtiment | bâtiment mixte | H7: GN 2 | GN 3 | CO 6 à CO 10 | L7: type_erp | categorie_erp | M7: reglementaire | N7: conception | exploitation | O7: architecte | P7: Ne pas confondre avec l'isolement vis-à-vis des tiers, qui suppose des exploitations sans lien. | Q7: a_verifier
A8: NOT-0007 | B8: T1 — Classement, champ d'application, seuils | C8: tiers contigu ou superposé | D8: Occupant distinct, contigu ou superposé, vis-à-vis duquel un degré d'isolement est exigé. | E8: le voisin | mitoyenneté | le logement au-dessus | le commerce en pied d'immeuble | H8: CO 6 | CO 7 | CO 8 | CO 9 | CO 10 | J8: arr. 31/01/1986 art. 5 | L8: corpus | type_erp | famille_habitation | M8: reglementaire | N8: conception | exploitation | O8: architecte | gestionnaire | P8: L'exigence est renforcée lorsque le tiers relève de l'habitation ou d'une ICPE. | Q8: a_verifier
A9: NOT-0008 | B9: T1 — Classement, champ d'application, seuils | C9: immeuble de grande hauteur | D9: Bâtiment dont le plancher bas du dernier niveau dépasse 50 m en habitation, 28 m dans les autres cas, soumis à un régime autonome. | E9: tour | IGH | immeuble de plus de 28 mètres | K9: CCH L. 146-1 et s. | CCH R. 146-1 et s. | arrêté du 30/12/2011 | L9: hauteur_plancher_bas | M9: reglementaire | N9: conception | exploitation | O9: architecte | gestionnaire | P9: Le régime IGH se substitue à l'ERP pour les dispositions générales et impose un service de sécurité permanent. | Q9: haute
A10: NOT-0009 | B10: T1 — Classement, champ d'application, seuils | C10: application aux bâtiments existants | D10: Régime déterminant dans quelle mesure les dispositions nouvelles s'appliquent à un bâtiment déjà édifié et ce que déclenchent des travaux. | E10: dois-je tout remettre aux normes | mon bâtiment date de 1985 | grand-père du bâtiment | H10: GN 6 | GN 7 | GN 10 | I10: R. 4211-1 et s. | J10: arr. 31/01/1986 — dispositions transitoires | L10: existant_ou_neuf | date_effet | M10: reglementaire | N10: conception | exploitation | O10: architecte | dirigeant | gestionnaire | P10: Question systématiquement sous-estimée. La réponse dépend de la date du permis, pas de la date de la demande. | Q10: a_verifier
A11: NOT-0010 | B11: T1 — Classement, champ d'application, seuils | C11: dérogation | D11: Autorisation de s'écarter d'une prescription, accordée après avis motivé de la commission de sécurité et assortie de mesures compensatoires. | E11: j'ai une dérogation | on peut y couper | faire une demande spéciale | H11: GN 4 | GN 5 | K11: CCH R. 143-11 (ex-R. 123-13) | L11: type_erp | categorie_erp | M11: reglementaire | N11: conception | exploitation | O11: architecte | P11: N'existe pas en tant que telle en code du travail : on y raisonne en démonstration d'équivalence du niveau de sécurité. | Q11: a_verifier
A12: NOT-0011 | B12: T1 — Classement, champ d'application, seuils | C12: mesure compensatoire | D12: Disposition supplémentaire justifiant qu'un niveau de sécurité équivalent est atteint malgré un écart à la règle. | E12: compensation | mesure de substitution | solution alternative | H12: GN 4 | GN 5 | L12: type_erp | categorie_erp | M12: doctrinal | N12: conception | exploitation | O12: architecte | P12: Le contenu relève de l'appréciation de la commission : le système doit orienter, pas trancher. | Q12: a_verifier
A13: NOT-0012 | B13: T1 — Classement, champ d'application, seuils | C13: installation classée pour la protection de l'environnement | D13: Régime distinct s'appliquant aux activités et stockages dépassant les seuils de la nomenclature. | E13: ICPE | rubrique 1510 | on est classé | arrêté préfectoral | K13: Code de l'environnement L. 511-1 et s. | nomenclature ICPE | L13: nature_risque | M13: reglementaire | N13: conception | exploitation | O13: dirigeant | gestionnaire | P13: En cas de concurrence avec le code du travail, la disposition la plus contraignante s'applique. | Q13: a_verifier
A14: NOT-0013 | B14: T2 — Accès des secours, implantation, façades | C14: voie engin | D14: Voie utilisable par les engins de secours, définie par des caractéristiques de largeur, force portante, pente et rayon de giration. | E14: accès pompiers | voie pompier | la route pour les camions | H14: CO 2 | CO 3 | CO 5 | J14: arr. 31/01/1986 art. 4 | L14: type_erp | categorie_erp | famille_habitation | M14: reglementaire | N14: conception | exploitation | O14: architecte | gestionnaire | Q14: haute
A15: NOT-0014 | B15: T2 — Accès des secours, implantation, façades | C15: voie échelle | D15: Section de voie engin permettant la mise en station des moyens élévateurs aériens. | E15: accès grande échelle | emplacement pour la nacelle | H15: CO 2 | CO 4 | CO 5 | J15: arr. 31/01/1986 art. 4 | L15: hauteur_plancher_bas | famille_habitation | M15: reglementaire | N15: conception | exploitation | O15: architecte | gestionnaire | Q15: a_verifier
A16: NOT-0015 | B16: T2 — Accès des secours, implantation, façades | C16: espace libre | D16: Espace permettant l'accès et la mise en œuvre des moyens de secours à défaut de voie engin. | E16: dégagement extérieur | la cour | H16: CO 2 | L16: type_erp | M16: reglementaire | N16: conception | exploitation | O16: architecte | Q16: a_verifier
A17: NOT-0016 | B17: T2 — Accès des secours, implantation, façades | C17: façade accessible | D17: Façade permettant aux services de secours d'accéder à tous les niveaux par des baies répondant à des caractéristiques définies. | E17: façade pompier | combien de côtés accessibles | H17: CO 2 | CO 3 | J17: arr. 31/01/1986 art. 4 | L17: categorie_erp | famille_habitation | M17: reglementaire | N17: conception | exploitation | O17: architecte | Q17: a_verifier
A18: NOT-0017 | B18: T2 — Accès des secours, implantation, façades | C18: défense extérieure contre l'incendie | D18: Ensemble des points d'eau incendie destinés à l'alimentation des moyens de lutte, dimensionné au niveau départemental. | E18: poteau incendie | borne à incendie | la bouche dans la rue | DECI | besoins en eau | K18: CGCT L. 2225-1 et s. | CGCT R. 2225-1 et s. | RDDECI départemental | L18: nature_risque | surface_local | M18: reglementaire | N18: conception | exploitation | O18: architecte | dirigeant | P18: Ne pas chercher dans l'arrêté de 1980 : la règle est départementale et varie d'un département à l'autre. | Q18: haute
A19: NOT-0018 | B19: T2 — Accès des secours, implantation, façades | C19: propagation du feu par les façades | D19: Règles limitant la transmission du feu d'un niveau à l'autre par la façade, notamment par la règle C + D. | E19: C+D | règle du C plus D | le feu qui monte par la façade | H19: CO 19 | CO 20 | CO 21 | CO 22 | J19: arr. 31/01/1986 | K19: instruction technique n° 249 | L19: type_erp | famille_habitation | M19: interpretatif | N19: conception | exploitation | O19: architecte | gestionnaire | Q19: a_verifier
A20: NOT-0019 | B20: T2 — Accès des secours, implantation, façades | C20: système d'isolation thermique par l'extérieur | D20: Complexe d'isolation rapporté en façade, soumis à des règles de recoupement de lame d'air et de protection des baies lorsque l'isolant est combustible. | E20: ITE | isolation par l'extérieur | on met de l'isolant sur la façade | rénovation énergétique | K20: instruction technique n° 249 | guides de préconisations ITE | L20: famille_habitation | type_erp | M20: interpretatif | N20: conception | exploitation | O20: architecte | gestionnaire | P20: Point de friction majeur entre performance énergétique et sécurité incendie en réhabilitation. | Q20: a_verifier
A21: NOT-0020 | B21: T3 — Structure, compartimentage, comportement au feu | C21: résistance au feu | D21: Aptitude d'un élément à conserver pendant une durée déterminée sa capacité portante (R), son étanchéité (E) et son isolation thermique (I). | E21: coupe-feu | CF 1 heure | pare-flamme | PF 1/2 heure | tenue au feu | degré coupe-feu | F21: CF (coupe-feu) -> EI ou REI (2004-03-22) | PF (pare-flamme) -> E ou EI partiel (2004-03-22) | SF (stabilité au feu) -> R (2004-03-22) | H21: CO 11 | CO 12 | I21: R. 4216-1 et s. | J21: arr. 31/01/1986 art. 7 et s. | K21: arrêté du 22/03/2004 | L21: categorie_erp | famille_habitation | hauteur_plancher_bas | M21: reglementaire | N21: conception | exploitation | O21: architecte | dirigeant | gestionnaire | P21: PIÈGE N°2 : « coupe-feu » ne figure plus dans les textes postérieurs à 2004 mais reste employé par tous. Chercher EI / REI. | Q21: haute
A22: NOT-0021 | B22: T3 — Structure, compartimentage, comportement au feu | C22: stabilité au feu des structures | D22: Durée pendant laquelle les éléments porteurs conservent leur capacité portante en situation d'incendie. | E22: SF 1 heure | tenue de la charpente | est-ce que ça tient | F22: SF -> R (2004-03-22) | H22: CO 12 | I22: R. 4216-1 et s. | J22: arr. 31/01/1986 art. 7 et s. | L22: categorie_erp | hauteur_plancher_bas | nb_niveaux | M22: reglementaire | N22: conception | exploitation | O22: architecte | dirigeant | P22: En code du travail, l'exigence de stabilité est ténue pour les bâtiments industriels : vérifier si elle procède plutôt de l'ICPE ou du contrat d'assurance. | Q22: a_verifier
A23: NOT-0022 | B23: T3 — Structure, compartimentage, comportement au feu | C23: procès-verbal de classement | D23: Document délivré par un laboratoire agréé attestant du classement de réaction ou de résistance au feu d'un produit ou d'un ouvrage. | E23: PV feu | certificat | fiche technique | attestation du fabricant | le doc du fournisseur | K23: arrêté du 21/11/2002 | arrêté du 22/03/2004 | L23: date_effet | M23: reglementaire | N23: conception | exploitation | O23: architecte | dirigeant | gestionnaire | P23: Vérifier la validité, le domaine d'emploi et la mise en œuvre couverte : un PV hors domaine ne vaut rien. | Q23: a_verifier
A24: NOT-0023 | B24: T3 — Structure, compartimentage, comportement au feu | C24: réaction au feu | D24: Aliment que constitue un matériau pour le développement du feu, exprimé par les euroclasses. | E24: M0 | M1 | classement au feu du revêtement | matériau ininflammable | A2-s1,d0 | Bfl-s1 | F24: M0 à M4 -> euroclasses A1 à F (2002-11-21) | H24: AM 1 à AM 8 | I24: R. 4216-1 et s. | J24: arr. 31/01/1986 | K24: arrêté du 21/11/2002 | L24: type_erp | niveau_local | M24: reglementaire | N24: conception | exploitation | O24: architecte | P24: Les classements M subsistent dans les documents anciens ; la table de correspondance figure à l'arrêté du 21/11/2002. | Q24: haute
A25: NOT-0024 | B25: T3 — Structure, compartimentage, comportement au feu | C25: local à risques particuliers | D25: Local classé à risques moyens ou importants en raison de son contenu ou de son activité, soumis à des exigences d'isolement renforcées. | E25: local technique | local à risque | la chaufferie | le local archives | réserve | G25: local à risques particuliers [CT] : le code du travail parle de locaux présentant des risques particuliers d'incendie ou d'explosion : périmètre et conséquences distincts | H25: CO 27 | CO 28 | I25: R. 4216-1 et s. | R. 4227-22 et s. | L25: nature_risque | surface_local | M25: reglementaire | N25: conception | exploitation | O25: architecte | dirigeant | Q25: haute
A26: NOT-0025 | B26: T3 — Structure, compartimentage, comportement au feu | C26: calfeutrement de traversée | D26: Rétablissement du degré coupe-feu d'une paroi traversée par un conduit, un câble ou une canalisation. | E26: rebouchage | on a percé la dalle | passage de câbles | trou dans le mur | H26: CO 30 | CO 31 | CO 32 | CO 33 | J26: arr. 31/01/1986 art. 25 et s. | L26: corpus | M26: reglementaire | N26: conception | exploitation | O26: architecte | gestionnaire | P26: Défaut le plus fréquent en patrimoine existant, généré par les passages successifs de réseaux. | Q26: a_verifier
A27: NOT-0026 | B27: T3 — Structure, compartimentage, comportement au feu | C27: clapet coupe-feu | D27: Dispositif d'obturation automatique rétablissant le degré coupe-feu d'une paroi traversée par un conduit aéraulique. | E27: clapet | volet coupe-feu | trappe dans la gaine | H27: CO 31 | K27: instruction technique n° 246 | L27: corpus | M27: reglementaire | N27: conception | exploitation | O27: architecte | dirigeant | gestionnaire | Q27: a_verifier
A28: NOT-0027 | B28: T3 — Structure, compartimentage, comportement au feu | C28: gaine technique | D28: Volume vertical ou horizontal contenant des conduits ou des réseaux, soumis à des règles de recoupement. | E28: gaine | trémie | colonne montante | le vide technique | H28: CO 30 à CO 33 | J28: arr. 31/01/1986 art. 25 et s. | L28: corpus | famille_habitation | M28: reglementaire | N28: conception | exploitation | O28: architecte | gestionnaire | Q28: a_verifier
A29: NOT-0028 | B29: T3 — Structure, compartimentage, comportement au feu | C29: plafond suspendu | D29: Plafond rapporté créant un plénum, soumis à des exigences de réaction au feu et de recoupement des vides. | E29: faux plafond | plénum | le vide au-dessus des dalles | H29: AM 4 | I29: R. 4216-1 et s. | L29: surface_local | M29: reglementaire | N29: conception | exploitation | O29: architecte | dirigeant | Q29: a_verifier
A30: NOT-0029 | B30: T3 — Structure, compartimentage, comportement au feu | C30: cloisonnement traditionnel | D30: Mode de distribution intérieure fondé sur des locaux et circulations recoupés, par opposition aux secteurs et compartiments. | E30: recoupement | cloisonnement | découper en zones | H30: CO 24 | CO 25 | CO 26 | L30: type_erp | categorie_erp | M30: reglementaire | N30: conception | exploitation | O30: architecte | Q30: a_verifier
A31: NOT-0030 | B31: T3 — Structure, compartimentage, comportement au feu | C31: secteur | D31: Mode de distribution alternatif au cloisonnement traditionnel, fondé sur des volumes séparés par des parois coupe-feu et des dispositifs particuliers. | E31: grande surface sans cloisons | zone | H31: CO 24 | CO 25 | L31: type_erp | categorie_erp | M31: reglementaire | N31: conception | exploitation | O31: architecte | Q31: a_verifier
A32: NOT-0031 | B32: T3 — Structure, compartimentage, comportement au feu | C32: compartiment | D32: Volume délimité par des parois coupe-feu au sein duquel l'évacuation est différée, admis dans certaines configurations. | E32: évacuation horizontale | transfert latéral | H32: CO 24 | CO 25 | L32: type_erp | categorie_erp | M32: reglementaire | N32: conception | exploitation | O32: architecte | Q32: a_verifier
A33: NOT-0032 | B33: T3 — Structure, compartimentage, comportement au feu | C33: volume libre intérieur | D33: Volume intéressant plusieurs niveaux, soumis à des dispositions particulières de désenfumage et d'évacuation. | E33: atrium | patio couvert | vide sur plusieurs étages | mezzanine ouverte | H33: CO 24 à CO 26 | K33: instruction technique n° 263 | L33: type_erp | categorie_erp | nb_niveaux | M33: interpretatif | N33: conception | exploitation | O33: architecte | Q33: a_verifier
A34: NOT-0033 | B34: T3 — Structure, compartimentage, comportement au feu | C34: bloc-porte palier | D34: Porte séparant un logement de la circulation commune, présentant un degré pare-flamme selon la famille. | E34: porte palière | porte d'entrée du logement | la porte du locataire | J34: arr. 31/01/1986 art. 11 | arr. 31/01/1986 art. 27 | arr. 31/01/1986 art. 32 | L34: famille_habitation | M34: reglementaire | N34: conception | exploitation | O34: gestionnaire | P34: Le remplacement par l'occupant d'un bloc-porte classé par un modèle du commerce est un point de contrôle récurrent. | Q34: a_verifier
A35: NOT-0034 | B35: T4 — Dégagements et évacuation | C35: dégagement | D35: Toute partie de la construction permettant le cheminement d'évacuation des occupants : porte, circulation, escalier, sortie. | E35: issue de secours | sortie de secours | porte de secours | les issues | la sortie | H35: CO 34 | CO 35 | CO 36 | CO 38 | CO 43 | I35: R. 4216-6 et s. | R. 4227-1 | R. 4227-4 | J35: arr. 31/01/1986 art. 26 et s. | L35: effectif_public | effectif_travailleurs | categorie_erp | M35: reglementaire | N35: conception | exploitation | O35: architecte | dirigeant | gestionnaire | P35: PIÈGE N°3 : « issue de secours » est un terme de chantier absent du règlement. Chercher « dégagement » ramène la règle ; « issue de secours » ne ramène que de la signalisation. | Q35: haute
A36: NOT-0035 | B36: T4 — Dégagements et évacuation | C36: unité de passage | D36: Unité de largeur servant au dimensionnement des dégagements. | E36: UP | largeur de porte | combien de centimètres | H36: CO 36 | CO 38 | I36: R. 4216-8 | L36: effectif_public | effectif_travailleurs | M36: reglementaire | N36: conception | exploitation | O36: architecte | dirigeant | Q36: haute
A37: NOT-0036 | B37: T4 — Dégagements et évacuation | C37: dégagement accessoire | D37: Dégagement compensant une insuffisance des dégagements normaux, comptabilisé de façon limitée. | E37: sortie de secours en plus | la petite porte du fond | H37: CO 34 | CO 39 | CO 41 | L37: effectif_public | M37: reglementaire | N37: conception | exploitation | O37: architecte | P37: Ne pas confondre avec le dégagement supplémentaire ni avec le dégagement de secours. | Q37: a_verifier
A38: NOT-0037 | B38: T4 — Dégagements et évacuation | C38: circulation horizontale | D38: Cheminement horizontal d'évacuation, éventuellement encloisonné et desservant les dégagements. | E38: couloir | coursive | le hall | circulation | G38: circulation horizontale commune [HAB] : en habitation, la notion est indissociable du régime des parties communes | H38: CO 34 | CO 44 | J38: arr. 31/01/1986 art. 26 et s. | L38: corpus | famille_habitation | M38: reglementaire | N38: conception | exploitation | O38: architecte | gestionnaire | Q38: a_verifier
A39: NOT-0038 | B39: T4 — Dégagements et évacuation | C39: escalier encloisonné | D39: Escalier isolé du reste de la construction par des parois coupe-feu et un dispositif de fermeture. | E39: cage d'escalier | escalier fermé | l'escalier | H39: CO 50 | CO 51 | CO 52 | CO 53 | CO 55 | J39: arr. 31/01/1986 art. 27 et s. | L39: categorie_erp | famille_habitation | M39: reglementaire | N39: conception | exploitation | O39: architecte | gestionnaire | Q39: haute
A40: NOT-0039 | B40: T4 — Dégagements et évacuation | C40: escalier à l'air libre | D40: Escalier dont une paroi comporte des vides suffisants sur l'extérieur, dispensé d'encloisonnement. | E40: escalier extérieur | escalier ouvert | H40: CO 52 | J40: arr. 31/01/1986 art. 27 et s. | L40: famille_habitation | categorie_erp | M40: reglementaire | N40: conception | exploitation | O40: architecte | gestionnaire | Q40: a_verifier
...

Sheet Assertions_négatives
A1: id | B1: notion | C1: corpus_interrogé | D1: assertion | E1: orientation | F1: références | G1: VALIDATION_EXPERT
A2: NEG-01 | B2: commission de sécurité | C2: HAB | D2: La notion de commission de sécurité n'existe pas pour les bâtiments d'habitation ordinaires. | E2: Le contrôle relève des pouvoirs de police du maire (CGCT L. 2212-2) et de la police de la sécurité des immeubles collectifs à usage principal d'habitation (CCH L. 511-1 et s.). | F2: CGCT L. 2212-2 | CCH L. 511-1 et s.
A3: NEG-02 | B3: commission de sécurité | C3: CT | D3: Le code du travail n'organise pas de commission de sécurité ni de visite périodique d'ouverture. | E3: Le contrôle est exercé a posteriori par l'agent de contrôle de l'inspection du travail (L. 4721-1, L. 4731-1). | F3: L. 4721-1 | L. 4731-1
A4: NEG-03 | B4: registre de sécurité | C4: HAB | D4: Aucune obligation générale de tenue d'un registre de sécurité n'est prévue en habitation ordinaire. | E4: Le régime du registre est propre aux ERP (CCH R. 143-34) et aux IGH. En habitation, la traçabilité relève de la prudence du propriétaire, non d'un texte. | F4: CCH R. 143-34 (ex-R. 123-51)
A5: NEG-04 | B5: espace d'attente sécurisé | C5: HAB | D5: La notion d'espace d'attente sécurisé n'existe pas dans le corpus habitation. | E5: Elle est propre aux ERP (CO 57 à CO 60) et aux lieux de travail (R. 4216-2-1). En habitation, la doctrine est le maintien dans le logement. | F5: CO 57 à CO 60 | R. 4216-2-1
A6: NEG-05 | B6: extincteur | C6: HAB | D6: Aucun texte n'impose d'extincteurs en parties communes d'un bâtiment d'habitation ordinaire. | E6: Leur présence procède d'une exigence d'assurance ou d'une décision de gestion ; une fois installés, ils doivent être entretenus.
A7: NEG-06 | B7: équipement d'alarme | C7: HAB | D7: Aucun équipement d'alarme générale n'est exigé dans les bâtiments d'habitation ordinaires. | E7: L'exigence n'apparaît que dans des régimes particuliers (logements-foyers, résidences services relevant du type J ou O au titre du règlement ERP).
A8: NEG-07 | B8: exercice d'évacuation | C8: HAB | D8: Aucun exercice d'évacuation périodique n'est imposé au propriétaire d'un bâtiment d'habitation. | E8: L'obligation semestrielle est propre au code du travail (R. 4227-39). En habitation, l'obligation se limite à l'information des occupants. | F8: R. 4227-39
A9: NEG-08 | B9: dérogation | C9: CT | D9: Le code du travail ne prévoit pas de mécanisme de dérogation comparable à celui des ERP. | E9: Il combine une obligation de résultat (L. 4121-1) et des prescriptions minimales : l'écart se justifie par une démonstration d'équivalence, non par une autorisation. | F9: L. 4121-1
A10: NEG-09 | B10: type et catégorie | C10: HAB | D10: Les bâtiments d'habitation ne sont ni typés ni catégorisés au sens du règlement ERP. | E10: Ils sont classés en familles (arr. 31/01/1986 art. 3). | F10: arr. 31/01/1986 art. 3
A11: NEG-10 | B11: famille | C11: ERP | D11: La notion de famille n'a pas cours pour les établissements recevant du public. | E11: Le classement ERP repose sur le type d'exploitation et la catégorie (GN 1, GN 2). | F11: GN 1 | GN 2
A12: NEG-11 | B12: coupe-feu (CF) | C12: tous | D12: Les appellations CF, PF et SF ne figurent plus dans les textes postérieurs à l'arrêté du 22 mars 2004. | E12: Elles subsistent dans les PV anciens et le langage courant ; la recherche doit porter sur R, E, I, EI, REI. | F12: arrêté du 22/03/2004
A13: NEG-12 | B13: point de rassemblement | C13: tous | D13: L'expression « point de rassemblement » n'est pas un terme réglementaire. | E13: Le code du travail impose l'évacuation vers un lieu sûr (R. 4227-1) ; la désignation du point relève de la consigne de sécurité incendie. | F13: R. 4227-1 | R. 4227-37
A14: NEG-13 | B14: équipier de première intervention (EPI) | C14: CT | D14: Les qualifications EPI, ESI, guide-file et serre-file ne figurent pas dans le code du travail. | E14: Le texte vise les travailleurs désignés pour mettre en œuvre les moyens de premiers secours (R. 4227-38). | F14: R. 4227-38
A15: NEG-14 | B15: RVRAT | C15: tous | D15: RVRAT n'est pas une notion réglementaire mais un sigle de bureau de contrôle. | E15: Le texte vise les vérifications techniques et leurs rapports (GE 6 à GE 10 ; R. 4224-17). | F15: GE 6 à GE 10 | R. 4224-17
A16: NEG-15 | B16: règle APSAD | C16: tous | D16: Les règles APSAD ne sont pas des textes réglementaires. | E16: Elles constituent des référentiels contractuels d'assurance : leur non-respect a des effets sur la garantie, non sur la conformité.
A17: NEG-16 | B17: sprinkleur | C17: HAB | D17: Aucun texte n'impose d'extinction automatique dans les bâtiments d'habitation ordinaires. | E17: L'exigence, lorsqu'elle existe, procède du régime ICPE d'un local annexe ou d'une clause d'assurance.
A18: NEG-17 | B18: détecteur de fumée normalisé (DAAF) | C18: ERP | D18: Le DAAF relève du régime des logements et non du règlement ERP. | E18: En ERP, la détection procède d'un SSI (MS 53 et s.). | F18: CCH L. 142-2 et s. | MS 53 et s.
A19: NEG-18 | B19: notice de sécurité | C19: CT | D19: Le code du travail n'impose pas de notice descriptive de sécurité au dossier de permis. | E19: Les obligations pèsent sur le maître d'ouvrage au titre de la conception des lieux de travail (R. 4211-1 et s.). | F19: R. 4211-1 et s.
A20: NEG-19 | B20: unité de passage | C20: HAB | D20: Le dimensionnement des dégagements en unités de passage n'est pas la logique du corpus habitation. | E20: Les exigences y sont fixées en valeurs absolues selon la famille (arr. 31/01/1986). | F20: arr. 31/01/1986
A21: NEG-20 | B21: effectif théorique du public | C21: CT | D21: L'effectif théorique du public n'a pas d'équivalent en code du travail. | E21: Le décompte y suit les règles des articles L. 1111-2 et L. 1111-3, de périmètre différent. | F21: L. 1111-2 | L. 1111-3

Sheet Variables
A1: id | B1: nom | C1: libellé | D1: type | E1: valeurs | F1: note
A2: VAR-01 | B2: corpus | C2: Corpus réglementaire applicable | D2: enum | E2: ERP | CT | HAB | IGH | ICPE | DECI | F2: Un même bâtiment peut relever de plusieurs corpus simultanément.
A3: VAR-02 | B3: type_erp | C3: Type d'exploitation ERP | D3: enum | E3: J | L | M | N | O | P | R | S | T | U | V | W | X | Y | PA | CTS | SG | PS | OA | REF | GA | EF
A4: VAR-03 | B4: categorie_erp | C4: Catégorie ERP | D4: enum | E4: 1 | 2 | 3 | 4 | 5 | F4: Déterminée par l'effectif ; conditionne l'essentiel des exigences.
A5: VAR-04 | B5: effectif_public | C5: Effectif théorique du public | D5: entier | F5: Mode de calcul propre à chaque type (dispositions particulières).
A6: VAR-05 | B6: effectif_travailleurs | C6: Effectif décompté au sens du code du travail | D6: entier | F6: Décompte L. 1111-2 ; seuil pivot : plus de 50 personnes.
A7: VAR-06 | B7: famille_habitation | C7: Famille du bâtiment d'habitation | D7: enum | E7: 1re | 2e | 3e A | 3e B | 4e
A8: VAR-07 | B8: hauteur_plancher_bas | C8: Hauteur du plancher bas du dernier niveau | D8: metres | F8: Bascule IGH : 50 m en habitation, 28 m pour les autres.
A9: VAR-08 | B9: nb_niveaux | C9: Nombre de niveaux / étages sur rez-de-chaussée | D9: entier
A10: VAR-09 | B10: date_effet | C10: Date de référence (permis, travaux, ou jour) | D10: date | F10: Détermine la version du texte applicable. Obligatoire sur toute requête.
A11: VAR-10 | B11: existant_ou_neuf | C11: Statut du bâtiment | D11: enum | E11: neuf | existant | existant_avec_travaux
A12: VAR-11 | B12: niveau_local | C12: Position du local | D12: enum | E12: sous-sol | rez-de-chaussee | etage | dernier_niveau
A13: VAR-12 | B13: surface_local | C13: Surface du local | D13: m2
A14: VAR-13 | B14: nature_risque | C14: Nature du risque du local | D14: enum | E14: courant | risques_moyens | risques_importants | ATEX
A15: VAR-14 | B15: stade | C15: Stade du projet | D15: enum | E15: conception | exploitation | F15: Le même sujet est traité dans deux séries d'articles distinctes.
A16: VAR-15 | B16: qualite_demandeur | C16: Qualité du demandeur | D16: enum | E16: maitre_ouvrage | maitre_oeuvre | exploitant | employeur | proprietaire | locataire | gestionnaire
A17: VAR-16 | B17: presence_public | C17: Présence de public | D17: booleen
A18: VAR-17 | B18: presence_travailleurs | C18: Présence de travailleurs | D18: booleen

Sheet Jeu_référence
A1: id | B1: profil | C1: question_utilisateur | D1: reformulation_normative | E1: corpus_attendu | F1: articles_attendus | G1: notions_attendues | H1: notions_ids | I1: variables_requises | J1: comportement_attendu | K1: difficulte | L1: commentaire_evaluateur | M1: VALIDATION_EXPERT | N1: REPONSE_SYSTEME
A2: REF-A-01 | B2: architecte | C2: Mon bâtiment abrite un restaurant, une salle de spectacle et des bureaux : c'est quoi comme ERP ? | D2: Selon quels critères l'établissement est-il classé par type et par catégorie, et comment sont traités les établissements comportant plusieurs types ? | E2: ERP | F2: GN 1|GN 2|GN 3 | G2: type d'exploitation|catégorie|groupement d'établissements | H2: NOT-0001|NOT-0002|NOT-0006 | I2: type_erp|effectif_public | J2: demander_precision | K2: 2 | L2: L'effectif de chaque activité doit être connu avant toute réponse.
A3: REF-A-02 | B3: architecte | C3: Qu'est-ce qui change entre une 5e catégorie et une 1re ? | D3: Quelles dispositions distinguent les établissements de la 5e catégorie de ceux des quatre premières catégories ? | E3: ERP | F3: GN 1|GN 2|CCH R. 143-19 | G3: catégorie|effectif théorique du public | H3: NOT-0002|NOT-0003 | I3: categorie_erp | J3: repondre | K3: 1 | L3: Question de cadrage, réponse structurelle.
A4: REF-A-03 | B4: architecte | C4: Quels textes s'appliquent exactement à mon projet ? | D4: Quelles dispositions générales, particulières au type et, le cas échéant, du code du travail sont applicables ? | E4: ERP|CT | F4: GN 1|GN 2|R. 4211-1 et s. | G4: type d'exploitation|catégorie | H4: NOT-0001|NOT-0002 | I4: type_erp|presence_travailleurs | J4: orienter_corpus | K4: 2 | L4: Test du réflexe de superposition ERP / code du travail.
A5: REF-A-04 | B5: architecte | C5: En réhabilitation, jusqu'où puis-je garder l'existant non conforme ? | D5: Dans quelles conditions les dispositions sont-elles applicables aux établissements existants et quels travaux déclenchent leur application ? | E5: ERP | F5: GN 6|GN 7|GN 10 | G5: application aux bâtiments existants | H5: NOT-0009 | I5: existant_ou_neuf|date_effet | J5: demander_precision | K5: 3 | L5: Sans date de permis, aucune réponse fiable.
A6: REF-A-05 | B6: architecte | C6: Si je dépasse 28 m je passe en IGH ? | D6: À partir de quelle hauteur du plancher bas du dernier niveau l'établissement relève-t-il du régime des immeubles de grande hauteur ? | E6: IGH|ERP | F6: CCH L. 146-1 et s.|arrêté du 30/12/2011 | G6: immeuble de grande hauteur | H6: NOT-0008 | I6: hauteur_plancher_bas | J6: repondre | K6: 2 | L6: Attention au seuil différent en habitation (50 m).
A7: REF-A-06 | B7: architecte | C7: Atténuation, aggravation, dérogation : quelle différence ? | D7: Dans quelles conditions des atténuations sont-elles accordées, des mesures aggravantes imposées ou une dérogation sollicitée ? | E7: ERP | F7: GN 4|GN 5|CCH R. 143-11 | G7: dérogation|mesure compensatoire | H7: NOT-0010|NOT-0011 | I7: type_erp|categorie_erp | J7: repondre | K7: 2 | L7: Terminer par l'orientation vers l'avis de commission.
A8: REF-A-07 | B8: architecte | C8: Comment se calcule l'effectif de mon ERP ? | D8: Selon quel mode de détermination l'effectif théorique du public est-il calculé ? | E8: ERP | F8: GN 1|GN 2|dispositions particulières au type | G8: effectif théorique du public | H8: NOT-0003 | I8: type_erp | J8: demander_precision | K8: 2 | L8: Le mode de calcul dépend du type.
A9: REF-A-08 | B9: architecte | C9: Le personnel compte-t-il dans l'effectif ? | D9: Dans quels types l'effectif du personnel s'ajoute-t-il à celui du public ? | E9: ERP | F9: GN 1|dispositions particulières au type | G9: effectif théorique du public|effectif (décompte code du travail) | H9: NOT-0003|NOT-0004 | I9: type_erp | J9: demander_precision | K9: 2 | L9: Piège classique : la règle varie selon le type.
A10: REF-A-09 | B10: architecte | C10: Les réserves et bureaux comptent-ils dans l'effectif ? | D10: Les locaux non accessibles au public sont-ils pris en compte dans la détermination de l'effectif théorique ? | E10: ERP|CT | F10: GN 1|R. 4211-1 et s. | G10: effectif théorique du public | H10: NOT-0003 | I10: type_erp | J10: orienter_corpus | K10: 2 | L10: Ces locaux relèvent du code du travail.
A11: REF-A-10 | B11: architecte | C11: Puis-je plafonner l'effectif par un engagement de l'exploitant ? | D11: Selon quelles modalités un effectif déclaré est-il rendu opposable à l'exploitant et contrôlé ? | E11: ERP | F11: GN 1|GE 2 et s. | G11: effectif théorique du public|registre de sécurité | H11: NOT-0003|NOT-0093 | I11: effectif_public | J11: repondre | K11: 3 | L11: Réponse partiellement doctrinale : avis de commission.
A12: REF-A-11 | B12: architecte | C12: Il me faut quelle largeur de voie pompier ? | D12: Quelles caractéristiques sont exigées pour les voies utilisables par les engins de secours et les voies échelles ? | E12: ERP | F12: CO 2|CO 3|CO 4|CO 5 | G12: voie engin|voie échelle|espace libre | H12: NOT-0013|NOT-0014|NOT-0015 | I12: categorie_erp|hauteur_plancher_bas | J12: repondre | K12: 1 | L12: Item de contrôle du rappel lexical de base.
A13: REF-A-12 | B13: architecte | C13: Combien de façades accessibles il me faut ? | D13: Quel nombre de façades accessibles l'établissement doit-il présenter et selon quelle définition sont-elles décomptées ? | E13: ERP | F13: CO 2|CO 3 | G13: façade accessible | H13: NOT-0016 | I13: categorie_erp | J13: demander_precision | K13: 2
A14: REF-A-13 | B14: architecte | C14: Mon bâtiment est mitoyen d'un logement : quel isolement ? | D14: Quels degrés d'isolement sont exigés vis-à-vis des tiers contigus ou superposés ? | E14: ERP|HAB | F14: CO 6|CO 7|CO 8|CO 9|CO 10|arr. 31/01/1986 art. 5 | G14: tiers contigu ou superposé | H14: NOT-0007 | I14: type_erp|famille_habitation | J14: orienter_corpus | K14: 2 | L14: Double corpus obligatoire.
A15: REF-A-14 | B15: architecte | C15: Commerce en RDC et logements au-dessus : comment on traite ? | D15: Selon quelles modalités l'isolement est-il assuré dans un bâtiment abritant un ERP et des locaux d'habitation ? | E15: ERP|HAB | F15: CO 6 à CO 10|arr. 31/01/1986 art. 5 | G15: tiers contigu ou superposé|famille | H15: NOT-0007|NOT-0005 | I15: type_erp|famille_habitation | J15: orienter_corpus | K15: 3
A16: REF-A-15 | B16: architecte | C16: C'est quoi la règle du C+D ? | D16: Dans quels cas la règle du C + D s'applique-t-elle au traitement des façades ? | E16: ERP|HAB | F16: CO 19|CO 20|CO 21|CO 22|instruction technique n° 249 | G16: propagation du feu par les façades | H16: NOT-0018 | I16: type_erp|famille_habitation | J16: repondre | K16: 2 | L16: Qualifier le niveau : interprétatif (IT).
A17: REF-A-16 | B17: architecte | C17: Je peux mettre un parking en sous-sol communiquant avec l'ERP ? | D17: À quelles conditions un parc de stationnement couvert peut-il communiquer avec l'établissement ? | E17: ERP | F17: CO 6 à CO 10|dispositions particulières type PS | G17: parc de stationnement couvert|tiers contigu ou superposé | H17: NOT-0085|NOT-0007 | I17: surface_local|niveau_local | J17: repondre | K17: 2
A18: REF-A-17 | B18: architecte | C18: Quelle stabilité au feu pour ma structure ? | D18: Quel degré de stabilité au feu est exigé des éléments porteurs ? | E18: ERP | F18: CO 11|CO 12 | G18: stabilité au feu des structures|résistance au feu | H18: NOT-0021|NOT-0020 | I18: categorie_erp|hauteur_plancher_bas|nb_niveaux | J18: demander_precision | K18: 2 | L18: Test du refus de répondre sans classement.
A19: REF-A-18 | B19: architecte | C19: R, E, I, REI : ça veut dire quoi et comment lire un PV ? | D19: Quelles sont les correspondances entre les critères R, E, I et les anciennes appellations, et quelles conditions un PV doit-il remplir ? | E19: ERP|CT|HAB | F19: arrêté du 22/03/2004 | G19: résistance au feu|procès-verbal de classement | H19: NOT-0020|NOT-0022 | I19: date_effet | J19: repondre | K19: 1 | L19: Item de correspondance lexicale pure.
A20: REF-A-19 | B20: architecte | C20: Je peux laisser ma charpente bois apparente ? | D20: Dans quels cas des éléments de structure en bois ou en acier peuvent-ils être laissés apparents ? | E20: ERP | F20: CO 11|CO 12 | G20: stabilité au feu des structures|réaction au feu | H20: NOT-0021|NOT-0023 | I20: categorie_erp|nb_niveaux | J20: demander_precision | K20: 3
A21: REF-A-20 | B21: architecte | C21: Comment traiter les percements dans les murs coupe-feu ? | D21: Quelles dispositions sont exigées pour le franchissement des parois délimitant un volume protégé ? | E21: ERP | F21: CO 30|CO 31|CO 32|CO 33 | G21: calfeutrement de traversée|clapet coupe-feu|gaine technique | H21: NOT-0025|NOT-0026|NOT-0027 | I21: corpus | J21: repondre | K21: 1
A22: REF-A-21 | B22: architecte | C22: Quels locaux sont des locaux à risques ? | D22: Quels locaux sont classés à risques moyens ou importants et quelles exigences en découlent ? | E22: ERP | F22: CO 27|CO 28 | G22: local à risques particuliers | H22: NOT-0024 | I22: nature_risque|surface_local | J22: repondre | K22: 1
A23: REF-A-22 | B23: architecte | C23: Comment choisir un revêtement de sol ou mural ? | D23: Quelles exigences de réaction au feu s'appliquent aux revêtements de sol, muraux et de plafond ? | E23: ERP | F23: AM 1 à AM 8|arrêté du 21/11/2002 | G23: réaction au feu|procès-verbal de classement | H23: NOT-0023|NOT-0022 | I23: type_erp|niveau_local | J23: repondre | K23: 1
A24: REF-A-23 | B24: architecte | C24: Et pour les faux plafonds, tentures et rideaux ? | D24: Quelles exigences s'appliquent aux plafonds suspendus, tentures et éléments de décoration ? | E24: ERP | F24: AM 4|AM 1 à AM 8 | G24: plafond suspendu|réaction au feu | H24: NOT-0028|NOT-0023 | I24: type_erp | J24: repondre | K24: 2
A25: REF-A-24 | B25: architecte | C25: Je peux faire une ITE avec un isolant combustible ? | D25: Dans quelles conditions un système d'isolation thermique par l'extérieur comportant un isolant combustible est-il admis ? | E25: ERP|HAB | F25: instruction technique n° 249 | G25: système d'isolation thermique par l'extérieur|propagation du feu par les façades | H25: NOT-0019|NOT-0018 | I25: type_erp|famille_habitation | J25: repondre | K25: 3 | L25: Niveau interprétatif à signaler.
A26: REF-A-25 | B26: architecte | C26: Le mobilier et les stands sont-ils concernés ? | D26: Le gros mobilier et les agencements sont-ils soumis à des exigences de réaction au feu et d'implantation ? | E26: ERP | F26: AM 15 à AM 19 | G26: réaction au feu|maintien des dégagements libres | H26: NOT-0023|NOT-0044 | I26: type_erp | J26: repondre | K26: 2
A27: REF-A-26 | B27: architecte | C27: Combien de sorties et quelle largeur pour mon effectif ? | D27: Selon quelles règles le nombre et la largeur des dégagements sont-ils déterminés ? | E27: ERP | F27: CO 34|CO 35|CO 36|CO 38 | G27: dégagement|unité de passage | H27: NOT-0034|NOT-0035 | I27: effectif_public | J27: demander_precision | K27: 1 | L27: Item pivot du jeu : effectif obligatoire.
A28: REF-A-27 | B28: architecte | C28: Dégagement normal, accessoire, de secours : quelle différence ? | D28: Quelles sont les définitions respectives des dégagements et dans quelle mesure chacun est-il comptabilisé ? | E28: ERP | F28: CO 34|CO 39|CO 41 | G28: dégagement|dégagement accessoire | H28: NOT-0034|NOT-0036 | I28: effectif_public | J28: repondre | K28: 2
A29: REF-A-28 | B29: architecte | C29: Quelle distance maximale jusqu'à une sortie ? | D29: Quelle est la distance maximale à parcourir, mesurée suivant l'axe des circulations ? | E29: ERP | F29: CO 43 | G29: distance à parcourir|dégagement | H29: NOT-0041|NOT-0034 | I29: type_erp|niveau_local | J29: repondre | K29: 1
A30: REF-A-29 | B30: architecte | C30: Mes portes doivent s'ouvrir vers l'extérieur ? | D30: À partir de quel effectif les portes s'ouvrent-elles dans le sens de l'évacuation ? | E30: ERP|CT | F30: CO 45|R. 4227-1 et s. | G30: sens d'ouverture des portes | H30: NOT-0042 | I30: effectif_public|effectif_travailleurs | J30: repondre | K30: 1 | L30: Double corpus attendu.
A31: REF-A-30 | B31: architecte | C31: Je peux mettre du contrôle d'accès sur les issues de secours ? | D31: Dans quelles conditions un dispositif de contrôle d'accès peut-il équiper une porte de sortie de secours ? | E31: ERP|CT | F31: CO 46|R. 4227-4|R. 4227-5 | G31: verrouillage des issues|dégagement | H31: NOT-0043|NOT-0034 | I31: corpus|effectif_public | J31: repondre | K31: 2 | L31: Le mot « issue de secours » doit être converti.
A32: REF-A-31 | B32: architecte | C32: Mes escaliers doivent être encloisonnés ? | D32: Quels escaliers doivent être encloisonnés, mis à l'air libre ou désenfumés ? | E32: ERP | F32: CO 50|CO 51|CO 52|CO 53|CO 55 | G32: escalier encloisonné|escalier à l'air libre | H32: NOT-0038|NOT-0039 | I32: categorie_erp|nb_niveaux | J32: demander_precision | K32: 2
A33: REF-A-32 | B33: architecte | C33: Comment traiter un atrium sur trois niveaux ? | D33: Selon quelles dispositions sont traités les volumes intéressant plusieurs niveaux ? | E33: ERP | F33: CO 24|CO 25|CO 26|instruction technique n° 263 | G33: volume libre intérieur|cloisonnement traditionnel|secteur | H33: NOT-0032|NOT-0029|NOT-0030 | I33: type_erp|nb_niveaux | J33: orienter_expertise | K33: 3 | L33: Relève souvent d'une ingénierie et d'un avis de commission.
A34: REF-A-33 | B34: architecte | C34: Dans quels cas j'ai droit à un escalier unique ? | D34: Dans quels cas la desserte des niveaux par un escalier unique est-elle admise ? | E34: ERP | F34: CO 39|CO 40 | G34: escalier unique|dégagement | H34: NOT-0040|NOT-0034 | I34: categorie_erp|effectif_public|nb_niveaux | J34: demander_precision | K34: 2
A35: REF-A-34 | B35: architecte | C35: Quels locaux dois-je désenfumer ? | D35: Quels locaux et circulations doivent être désenfumés et à partir de quels seuils ? | E35: ERP | F35: DF 4|DF 5|DF 6|instruction technique n° 246 | G35: désenfumage|local sans ouverture sur l'extérieur | H35: NOT-0048|NOT-0052 | I35: surface_local|niveau_local | J35: repondre | K35: 1
A36: REF-A-35 | B36: architecte | C36: Naturel ou mécanique, comment je choisis ? | D36: Selon quels critères le désenfumage naturel ou mécanique est-il retenu et quels taux sont exigés ? | E36: ERP | F36: DF 4 et s.|instruction technique n° 246 | G36: désenfumage|surface utile d'évacuation des fumées|amenée d'air | H36: NOT-0048|NOT-0050|NOT-0051 | I36: surface_local|niveau_local | J36: repondre | K36: 2
A37: REF-A-36 | B37: architecte | C37: Comment intégrer les exutoires sans casser l'architecture ? | D37: Quelles règles d'implantation, de surface et de commande s'appliquent aux exutoires et amenées d'air ? | E37: ERP | F37: DF 4 à DF 8|instruction technique n° 246 | G37: dispositif d'évacuation naturelle de fumées et de chaleur|amenée d'air | H37: NOT-0049|NOT-0051 | I37: surface_local | J37: repondre | K37: 2 | L37: La partie esthétique est hors périmètre : le signaler.
A38: REF-A-37 | B38: architecte | C38: Un atrium relève d'une approche particulière ? | D38: Dans quels cas un volume de grande hauteur relève-t-il de dispositions particulières ou d'une ingénierie du désenfumage ? | E38: ERP | F38: instruction technique n° 246|instruction technique n° 263 | G38: volume libre intérieur|désenfumage | H38: NOT-0032|NOT-0048 | I38: nb_niveaux | J38: orienter_expertise | K38: 3
A39: REF-A-38 | B39: architecte | C39: Où mettre la chaufferie et le TGBT ? | D39: Quelles conditions d'implantation, d'isolement et de ventilation s'appliquent aux chaufferies et locaux électriques ? | E39: ERP | F39: CH 5 à CH 8|EL 4 à EL 8|CO 27|CO 28 | G39: local à risques particuliers | H39: NOT-0024 | I39: nature_risque | J39: repondre | K39: 2
A40: REF-A-39 | B40: architecte | C40: Quelles exigences pour l'éclairage de sécurité ? | D40: Quelles exigences s'appliquent à l'éclairage de sécurité d'évacuation et d'ambiance ? | E40: ERP|CT | F40: EC 7 à EC 15|R. 4227-13|R. 4227-14 | G40: éclairage de sécurité | H40: NOT-0065 | I40: corpus|effectif_public | J40: repondre | K40: 1
...

Sheet Jeu_adverse
A1: id | B1: famille_de_piege | C1: question_utilisateur | D1: comportement_attendu | E1: reponse_attendue_resume | F1: articles_attendus | G1: corpus | H1: note_evaluateur | I1: VALIDATION_EXPERT | J1: REPONSE_SYSTEME
A2: ADV-01 | B2: P1-absence | C2: Quelle est la périodicité de visite de la commission de sécurité pour mon immeuble d'habitation ? | D2: signaler_absence | E2: Il n'existe pas de commission de sécurité pour l'habitation ordinaire ; orienter vers les pouvoirs de police du maire. | F2: CGCT L. 2212-2|CCH L. 511-1 et s. | G2: HAB | H2: Un RAG naïf remontera les articles GE de l'arrêté de 1980.
A3: ADV-02 | B3: P1-absence | C3: Combien d'extincteurs dois-je installer par palier dans ma résidence ? | D3: signaler_absence | E3: Aucune obligation réglementaire en habitation ordinaire ; renvoyer au contrat d'assurance. | G3: HAB | H3: Le système risque de transposer R. 4227-29 (un extincteur pour 200 m²).
A4: ADV-03 | B4: P1-absence | C4: Quel type d'équipement d'alarme dois-je installer dans mon immeuble de logements ? | D4: signaler_absence | E4: Aucun équipement d'alarme générale n'est exigé en habitation ordinaire, hors régimes particuliers. | G4: HAB | H4: Risque de transposition des types 1 à 4 du règlement ERP.
A5: ADV-04 | B5: P1-absence | C5: Où placer les espaces d'attente sécurisés dans mes logements ? | D5: signaler_absence | E5: La notion d'EAS est propre aux ERP et aux lieux de travail ; elle n'existe pas en habitation. | F5: CO 57 à CO 60|R. 4216-2-1 | G5: HAB | H5: Le mot EAS est très saillant : forte attraction sémantique.
A6: ADV-05 | B6: P1-absence | C6: À quelle fréquence dois-je organiser un exercice d'évacuation avec mes locataires ? | D6: signaler_absence | E6: Aucun exercice périodique n'est imposé en habitation ; l'obligation semestrielle est propre au code du travail. | F6: R. 4227-39 | G6: HAB
A7: ADV-06 | B7: P1-absence | C7: Quelle catégorie de SSI faut-il pour mon immeuble de 3e famille B ? | D7: signaler_absence | E7: Les catégories de SSI relèvent du règlement ERP ; l'habitation ne connaît pas ce classement. | F7: MS 53 à MS 60 | G7: HAB
A8: ADV-07 | B8: P1-absence | C8: Ma commission de sécurité est passée dans mon atelier, dois-je lever les réserves ? | D8: signaler_absence | E8: Le code du travail n'organise pas de commission de sécurité ; le contrôle relève de l'inspection du travail. | F8: L. 4721-1 | G8: CT | H8: Confusion fréquente chez les dirigeants dont l'établissement est aussi ERP.
A9: ADV-08 | B9: P1-absence | C9: Quelle est la famille de mon magasin de 800 m² ? | D9: signaler_absence | E9: Le classement en familles est propre à l'habitation ; un magasin relève du type et de la catégorie ERP. | F9: GN 1|GN 2 | G9: ERP
A10: ADV-09 | B10: P1-absence | C10: Quelle est la catégorie ERP de mon immeuble de logements ? | D10: signaler_absence | E10: Les bâtiments d'habitation ne sont ni typés ni catégorisés ; ils relèvent des familles. | F10: arr. 31/01/1986 art. 3 | G10: HAB
A11: ADV-10 | B11: P1-absence | C11: Quel est le nombre d'unités de passage exigé dans mes circulations communes d'immeuble ? | D11: signaler_absence | E11: Le dimensionnement en unités de passage n'est pas la logique du corpus habitation. | F11: arr. 31/01/1986 | G11: HAB
A12: ADV-11 | B12: P1-absence | C12: Quelle dérogation demander à l'inspection du travail pour mes dégagements insuffisants ? | D12: signaler_absence | E12: Le code du travail ne connaît pas la dérogation ERP ; l'écart se justifie par une démonstration d'équivalence. | F12: L. 4121-1 | G12: CT
A13: ADV-12 | B13: P1-absence | C13: Quelle notice de sécurité joindre au permis pour mon bâtiment industriel sans public ? | D13: signaler_absence | E13: La notice descriptive de sécurité est une pièce du dossier ERP ; hors ERP les obligations sont celles du maître d'ouvrage. | F13: R. 4211-1 et s. | G13: CT
A14: ADV-13 | B14: P2-lexique | C14: Quel degré CF faut-il pour mes planchers ? | D14: repondre | E14: Convertir CF en EI/REI, puis demander la famille ou la catégorie avant de répondre. | F14: arrêté du 22/03/2004 | G14: tous | H14: Le terme CF n'existe plus dans les textes postérieurs à 2004.
A15: ADV-14 | B15: P2-lexique | C15: Mes cloisons doivent-elles être M1 ? | D15: repondre | E15: Convertir le classement M en euroclasses et rappeler la table de correspondance. | F15: arrêté du 21/11/2002 | G15: tous
A16: ADV-15 | B16: P2-lexique | C16: Combien d'issues de secours dois-je prévoir ? | D16: repondre | E16: Convertir « issue de secours » en dégagement, puis appliquer les règles de nombre et de largeur. | F16: CO 34|CO 38|R. 4216-6 et s. | G16: ERP|CT | H16: PIÈGE N°3 : la recherche littérale ne ramène que de la signalisation.
A17: ADV-16 | B17: P2-lexique | C17: Mon alarme doit-elle être reliée aux pompiers ? | D17: repondre | E17: Distinguer alarme (occupants) et alerte (secours) avant de répondre. | F17: R. 4227-34 à R. 4227-37 | G17: CT | H17: PIÈGE N°4.
A18: ADV-17 | B18: P2-lexique | C18: Faut-il un RVRAT tous les ans ? | D18: signaler_non_reglementaire | E18: RVRAT est un sigle de bureau de contrôle ; le terme réglementaire est la vérification technique et son rapport. | F18: GE 6 à GE 10|R. 4224-17 | G18: ERP|CT
A19: ADV-18 | B19: P2-lexique | C19: Combien d'EPI dois-je former dans mon entreprise ? | D19: signaler_non_reglementaire | E19: EPI ne figure pas dans le code ; le texte vise les travailleurs désignés pour mettre en œuvre les moyens de premiers secours. | F19: R. 4227-38 | G19: CT | H19: Risque supplémentaire de confusion avec équipement de protection individuelle.
A20: ADV-19 | B20: P2-lexique | C20: Où doit être matérialisé le point de rassemblement réglementaire ? | D20: signaler_non_reglementaire | E20: L'expression n'est pas réglementaire ; le texte vise l'évacuation vers un lieu sûr. | F20: R. 4227-1|R. 4227-37 | G20: CT
A21: ADV-20 | B21: P2-lexique | C21: Quel est le degré SF de ma charpente ? | D21: repondre | E21: Convertir SF en R et préciser que l'exigence dépend du corpus applicable. | F21: arrêté du 22/03/2004|CO 12 | G21: tous
A22: ADV-21 | B22: P2-lexique | C22: Mon local à risques particuliers doit-il être désenfumé ? (atelier avec salariés) | D22: orienter_corpus | E22: La notion ERP de local à risques particuliers n'a pas le même périmètre que celle du code du travail. | F22: CO 27|CO 28|R. 4227-22 et s. | G22: CT|ERP | H22: Faux ami inter-corpus.
A23: ADV-22 | B23: P2-lexique | C23: Quelle est la surface de désenfumage de mon exutoire de 2 m² ? | D23: demander_precision | E23: Distinguer surface géométrique et surface utile d'évacuation des fumées avant tout calcul. | F23: instruction technique n° 246 | G23: ERP
A24: ADV-23 | B24: P3-version | C24: Que dit l'article R. 123-51 du CCH sur le registre de sécurité ? | D24: repondre | E24: Article recodifié : R. 143-34 depuis le 1er juillet 2021. Répondre sur la version en vigueur en signalant la correspondance. | F24: CCH R. 143-34 (ex-R. 123-51) | G24: ERP
A25: ADV-24 | B25: P3-version | C25: Mon obligation de détecteur de fumée est-elle bien à l'article L. 129-8 du CCH ? | D25: repondre | E25: Recodifié en L. 142-2 et suivants depuis 2021. | F25: CCH L. 142-2 et s. | G25: HAB
A26: ADV-25 | B26: P3-version | C26: Que prévoit l'article R. 232-12-2 du code du travail sur les dégagements ? | D26: repondre | E26: Article issu de l'ancienne numérotation, recodifié en R. 4227-x depuis 2008. | F26: R. 4227-1 et s. | G26: CT
A27: ADV-26 | B27: P3-version | C27: Mon bâtiment a un permis de 1978 : quelles règles habitation s'appliquent ? | D27: demander_precision | E27: Vérifier si l'arrêté du 10 septembre 1970 était applicable et ce que les travaux ultérieurs ont déclenché. | F27: arrêté du 10/09/1970|arr. 31/01/1986 | G27: HAB | H27: Test de la gestion de la date d'effet.
A28: ADV-27 | B28: P3-version | C28: L'arrêté de 1980 s'applique-t-il tel qu'il a été publié ? | D28: repondre | E28: Le texte a fait l'objet de très nombreuses modifications : répondre sur la version consolidée en vigueur. | F28: arrêté du 25/06/1980 | G28: ERP
A29: ADV-28 | B29: P3-version | C29: Mon PV feu de 1998 est-il toujours valable ? | D29: demander_precision | E29: Vérifier le domaine d'emploi, la validité et la correspondance avec le système européen. | F29: arrêté du 22/03/2004|arrêté du 21/11/2002 | G29: tous
A30: ADV-29 | B30: P3-version | C30: Quelle version de l'IT 246 dois-je appliquer à mon projet déposé l'an dernier ? | D30: demander_precision | E30: La version applicable dépend de la date de dépôt : demander la date exacte. | F30: instruction technique n° 246 | G30: ERP
A31: ADV-30 | B31: P3-version | C31: Le CHSCT doit-il être consulté sur mon projet de réaménagement ? | D31: repondre | E31: Le CHSCT a été remplacé par le CSE : répondre sur le régime en vigueur. | F31: L. 2312-8|L. 2312-9 | G31: CT
A32: ADV-31 | B32: P4-normativite | C32: L'APSAD R1 m'oblige à installer un sprinkleur, c'est bien réglementaire ? | D32: signaler_non_reglementaire | E32: Les règles APSAD sont des référentiels contractuels d'assurance, sans portée réglementaire. | F32: R. 4227-30 | G32: CT | H32: Item central du produit.
A33: ADV-32 | B33: P4-normativite | C33: La norme NF S 61-931 m'impose un coordonnateur SSI, quel article la rend obligatoire ? | D33: repondre | E33: La norme n'est opposable que par le renvoi qu'y opère le règlement : qualifier le fondement. | F33: MS 53 et s.|norme NF S 61-931 | G33: ERP | H33: Ne jamais restituer le contenu de la norme.
A34: ADV-33 | B34: P4-normativite | C34: Mon assureur exige un mur coupe-feu 4 heures, la réglementation le permet-elle ? | D34: signaler_non_reglementaire | E34: Exigence contractuelle excédant la règle : distinguer conformité et garantie. | G34: tous
A35: ADV-34 | B35: P4-normativite | C35: Le SDIS m'a demandé une citerne de 120 m³, sur quel texte ? | D35: orienter_corpus | E35: La DECI est fixée par le règlement départemental, non par l'arrêté de 1980. | F35: CGCT R. 2225-1 et s.|RDDECI départemental | G35: DECI
A36: ADV-35 | B36: P4-normativite | C36: La commission a émis un avis défavorable : cela vaut-il obligation de travaux ? | D36: orienter_expertise | E36: L'avis est consultatif ; la décision appartient à l'autorité de police. Qualifier le niveau doctrinal. | F36: CCH R. 143-1 et s. | G36: ERP
A37: ADV-36 | B37: P4-normativite | C37: Le guide de préconisations ITE a-t-il valeur réglementaire ? | D37: signaler_non_reglementaire | E37: Document interprétatif : l'opposabilité procède de l'IT 249 et des avis techniques. | F37: instruction technique n° 249 | G37: tous
A38: ADV-37 | B38: P4-normativite | C38: Mon bureau de contrôle exige un désenfumage que le texte ne prévoit pas. | D38: orienter_expertise | E38: Distinguer prescription réglementaire, exigence contractuelle de mission et préconisation. | G38: tous
A39: ADV-38 | B39: P4-normativite | C39: Une circulaire interdit les véhicules électriques en sous-sol, est-ce opposable ? | D39: signaler_non_reglementaire | E39: Vérifier l'existence, la nature et la portée du document invoqué avant toute réponse. | G39: HAB | H39: Test de résistance à la prémisse fausse.
A40: ADV-39 | B40: P5-variable | C40: Quel degré coupe-feu pour mes planchers ? | D40: demander_precision | E40: Demander la famille (habitation) ou le type et la catégorie (ERP) avant toute réponse. | G40: tous | H40: Item pivot : le système ne doit rien produire.
...

Sheet Suivi_validation
A1: Suivi de la validation experte
A3: Jeu | B3: Items | C3: Validés OK | D3: À corriger | E3: À supprimer | F3: Restant | G3: Avancement
A4: Thésaurus | B4: 96 | C4: =COUNTIF(Thésaurus!$R$2:$R$97,"OK") -> 0 | D4: =COUNTIF(Thésaurus!$R$2:$R$97,"A CORRIGER") -> 0 | E4: =COUNTIF(Thésaurus!$R$2:$R$97,"A SUPPRIMER") -> 0 | F4: =B4-C4-D4-E4 -> 96 | G4: =IFERROR(C4/B4,0) -> 0
A5: Assertions négatives | B5: 20 | C5: =COUNTIF(Assertions_négatives!$G$2:$G$21,"OK") -> 0 | D5: =COUNTIF(Assertions_négatives!$G$2:$G$21,"A CORRIGER") -> 0 | E5: =COUNTIF(Assertions_négatives!$G$2:$G$21,"A SUPPRIMER") -> 0 | F5: =B5-C5-D5-E5 -> 20 | G5: =IFERROR(C5/B5,0) -> 0
